<?xml version="1.0"?>

<robot name="aeroarms" xmlns:xacro="http://ros.org/wiki/xacro">
  <!-- Properties -->
  <xacro:property name="model_name" value="aeroarms_hecatonquiros_collision" />
  <xacro:property name="namespace" value="" />
  <xacro:property name="rotor_velocity_slowdown_sim" value="10" />
  <xacro:property name="mesh_file" value="multirotor.dae" />
  <xacro:property name="mesh_scale" value=".001 .001 .001"/>
  <xacro:property name="mesh_scale_prop" value=".001 .001 .001"/>
  <!--xacro:property name="mass" value="5.850" /--> <!-- [kg] -->
  <xacro:property name="mass" value="0.5" />
  <xacro:property name="body_width" value="0.8" /> <!-- [m] -->
  <xacro:property name="body_height" value="0.6" /> <!-- [m] -->
  <xacro:property name="mass_rotor" value="0.005" /> <!-- [kg] -->
  <xacro:property name="rotor_offset_top" value="0.0" /> <!-- [m] -->
  <xacro:property name="radius_rotor" value="0.19" /> <!-- [m] -->
  <xacro:property name="motor_constant" value="20.0e-06" /> <!-- [kg.m/s^2] -->
  <xacro:property name="moment_constant" value="0.12" /> <!-- [m] -->
  <xacro:property name="time_constant_up" value="0.0125" /> <!-- [s] -->
  <xacro:property name="time_constant_down" value="0.025" /> <!-- [s] -->
  <xacro:property name="max_rot_velocity" value="1100" /> <!-- [rad/s] -->
  <xacro:property name="sin30" value="0.5" />
  <xacro:property name="cos30" value="0.866025403784" />
  <xacro:property name="sqrt2" value="1.4142135623730951" />
  <xacro:property name="rotor_drag_coefficient" value="8.06428e-04" />
  <xacro:property name="rolling_moment_coefficient" value="0.000001" />
  <xacro:property name="color" value="$(arg visual_material)" />

  <!--Heca arms parameters-->
  <xacro:property name="PI" value="3.1415926535897931"/>
  <!--xacro:property name="h_mass" value="1" /--> 
  <xacro:property name="width" value="0.1" /> <!-- Square dimensions (widthxwidth) of beams -->
  <xacro:property name="height1" value="2" /> <!-- Link 1 -->
  <xacro:property name="height2" value="1" /> <!-- Link 2 -->
  <xacro:property name="height3" value="1" /> <!-- Link 3 -->
  <!--Heca arms parameters-->

<gazebo>
  <plugin name="gazebo_ros_control" filename="libgazebo_ros_control.so">
    <robotNamespace>/aeroarms</robotNamespace>
    <robotSimType>gazebo_ros_control/DefaultRobotHWSim</robotSimType>
  </plugin>
</gazebo>


  <!-- Property Blocks -->
  <xacro:property name="body_inertia">
    <inertia ixx="0.287" ixy="0.0" ixz="0.0" iyy="0.287" iyz="0.0" izz="0.468" /> <!-- [kg.m^2] [kg.m^2] [kg.m^2] [kg.m^2] [kg.m^2] [kg.m^2] -->
  </xacro:property>

  <!-- inertia of a single rotor, assuming it is a cuboid. Height=3mm, width=15mm -->
  <xacro:property name="rotor_inertia">
    <inertia
    ixx="${1/12 * mass_rotor * (0.015 * 0.015 + 0.003 * 0.003) * rotor_velocity_slowdown_sim}"
    iyy="${1/12 * mass_rotor * (4 * radius_rotor * radius_rotor + 0.003 * 0.003) * rotor_velocity_slowdown_sim}"
    izz="${1/12 * mass_rotor * (4 * radius_rotor * radius_rotor + 0.015 * 0.015) * rotor_velocity_slowdown_sim}"
    ixy="0.0" ixz="0.0"  iyz="0.0" /> <!-- [kg.m^2] [kg.m^2] [kg.m^2] [kg.m^2] [kg.m^2] [kg.m^2] -->
  </xacro:property>

  <!--Property cylinder_camera-->
  <xacro:property name="camera_cylinder">
    <cylinder length="0.001" radius="0.01" />
  </xacro:property>

  <!-- Included URDF Files -->
  <xacro:include filename="$(find arm_description)/urdf/multirotor_base.xacro" />
  <xacro:include filename="$(find arm_description)/urdf/component_snippets.xacro" />
  <xacro:include filename="$(find arm_description)/models/aeroarms_hecatonquiros_collision/arm.transmission.xacro" />
  <xacro:include filename="$(find arm_description)/models/aeroarms_hecatonquiros_collision/model.gazebo" />

  <!-- Instantiate multirotor_base_macro once -->
  <xacro:multirotor_base_macro
    model_name="${model_name}"
    robot_namespace="${namespace}"
    mass="${mass}"
    body_width="${body_width}"
    body_height="${body_height}"
    mesh_file="${mesh_file}"
    mesh_scale="${mesh_scale}"
    color="DarkGrey"
    >
    <xacro:insert_block name="body_inertia" />
  </xacro:multirotor_base_macro>

  <xacro:camera_macro
    namespace="${namespace}"
    parent_link="base_link"
    camera_suffix="0"
    frame_rate="10"
    horizontal_fov="1.07079633"
    image_width="800"
    image_height="600"
    image_format="R8G8B8"
    min_distance="0.01"
    max_distance="100"
    noise_mean="0"
    noise_stddev="0"
    enable_visual="true"
    >
    <xacro:insert_block name="camera_cylinder"/>
    <origin xyz="0 0 -0.10" rpy="0 1.57 0" />
  </xacro:camera_macro>

  <link name="camera_depth_base_link"></link>
  <joint name="camera_depth_base_joint" type="fixed">
    <origin xyz="0.4 0 0" rpy="0 0 0"/>
    <parent link="base_link"/>
    <child link="camera_depth_base_link"/>
  </joint>

  <link name="camera_depth_link"></link>
  <joint name="camera_depth_joint" type="fixed">
    <origin xyz="0 0 0" rpy="${-pi/2} 0 ${-pi/2} "/>
    <parent link="camera_depth_base_link"/>
    <child link="camera_depth_link"/>
  </joint>

  <!-- Base -->
  
  
    <link name="left/arm_0_bottom">
    
      <visual>
         <geometry>
         <box size="0.02 0.02 0.02"/>
            <!--mesh filename="package://arm_description/meshes/new_meshes/arm_0_attachment.stl" /-->
         </geometry>
          <origin rpy="0 0 0" xyz="0 0 0" />
      </visual>
      <collision>
      <origin rpy="0 0 0" xyz="0 0 0" />
            <geometry>
        <box size="0.02 0.02 0.02"/>
      </geometry>
      </collision>

          <inertial>
      <origin rpy="0 0 0" xyz="0 0 0" />
      <mass value="${mass}"/>
      <inertia
	  ixx="${mass / 12.0 * (width*width + height1*height1)}" ixy="0.0" ixz="0.0"
	  iyy="${mass / 12.0 * (height1*height1 + width*width)}" iyz="0.0"
	  izz="${mass / 12.0 * (width*width + width*width)}"/>
    </inertial>

   </link>
   <joint name="left/arm_0_bottom_joint" type="continuous">
      <parent link="base_link" />
      <child link="left/arm_0_bottom" />
      <origin rpy="0 0 0" xyz="0 0.1 -0.15" />
   </joint>



   
   <link name="left/arm_1">
   
      <visual>
         <geometry>
         <box size="0.02 0.02 0.4"/>
            <!--mesh filename="package://arm_description/meshes/new_meshes/arm_1.stl"  /-->
         </geometry>
         <origin rpy="0 0 ${pi}" xyz="0 0 0" />
      </visual>
            <collision>
             <origin rpy="0 0 ${pi}" xyz="0 0 0" />
            <geometry>
        <box size="0.02 0.02 0.4"/>
      </geometry>
      </collision>

    <inertial>
      <origin rpy="0 0 0" xyz="0 0 0" />
      <mass value="${mass}"/>
      <inertia
	  ixx="${mass / 12.0 * (width*width + height1*height1)}" ixy="0.0" ixz="0.0"
	  iyy="${mass / 12.0 * (height1*height1 + width*width)}" iyz="0.0"
	  izz="${mass / 12.0 * (width*width + width*width)}"/>
    </inertial>

   </link>
   <joint name="left/arm_1_joint" type="continuous">
      <parent link="left/arm_0_bottom" />
      <child link="left/arm_1" />
      <origin xyz="0 0 -0.06" rpy="0 ${3*pi/2} 0" />
   </joint>

   <link name="left/arm_final">
   
      <visual>
         <geometry>
         <box size="0.02 0.02 0.4"/>
            <!--mesh filename="package://arm_description/meshes/new_meshes/arm_1.stl"  /-->
         </geometry>
         <origin rpy="0 0 0" xyz="0 0 0" />
      </visual>
            <collision>
             <origin rpy="0 0 0" xyz="0 0 0" />
            <geometry>
        <box size="0.02 0.02 0.4"/>
      </geometry>
      </collision>

    <inertial>
      <origin rpy="0 0 0" xyz="0 0 0" />
      <mass value="${mass}"/>
      <inertia
	  ixx="${mass / 12.0 * (width*width + height1*height1)}" ixy="0.0" ixz="0.0"
	  iyy="${mass / 12.0 * (height1*height1 + width*width)}" iyz="0.0"
	  izz="${mass / 12.0 * (width*width + width*width)}"/>
    </inertial>

   </link>
   <joint name="left/arm_final_joint" type="fixed">
      <parent link="left/arm_1" />
      <child link="left/arm_final" />
      <origin xyz="-0.06 0 -0.06" rpy="0 0 0" />
   </joint>
 
  
<!--RIGHT ARMMMMMMMMMMMMMMMMMMMMMMMMMMMMMMMMMMMMMMMMMMMMMMMMMMMMMMMM-->


<link name="right/arm_0_bottom">

      <visual>
         <geometry>
         <box size="0.02 0.02 0.02"/>
            <!--mesh filename="package://arm_description/meshes/new_meshes/arm_0_attachment.stl" /-->
         </geometry>
          <origin rpy="0 0 0" xyz="0 0 0" />
      </visual>
    <collision>
    <origin rpy="0 0 0" xyz="0 0 0" />
            <geometry>
        <box size="0.02 0.02 0.02"/>
      </geometry>
      </collision>

          <inertial>
      <origin rpy="0 0 0" xyz="0 0 0" />
      <mass value="${mass}"/>
      <inertia
	  ixx="${mass / 12.0 * (width*width + height1*height1)}" ixy="0.0" ixz="0.0"
	  iyy="${mass / 12.0 * (height1*height1 + width*width)}" iyz="0.0"
	  izz="${mass / 12.0 * (width*width + width*width)}"/>
    </inertial>

   </link>
   <joint name="right/arm_0_bottom_joint" type="continuous">
      <parent link="base_link" />
      <child link="right/arm_0_bottom" />
      <origin rpy="0 0 0" xyz="0 -0.1 -0.15" />
   </joint>



   
   <link name="right/arm_1">
   <!--self_collide>0</self_collide-->
      <visual>
         <geometry>
         <box size="0.02 0.02 0.4"/>
            <!--mesh filename="package://arm_description/meshes/new_meshes/arm_1.stl"  /-->
         </geometry>
         <origin rpy="0 0 ${pi}" xyz="0 0 0" />
      </visual>
            <collision>
             <origin rpy="0 0 ${pi}" xyz="0 0 0" />
            <geometry>
        <box size="0.02 0.02 0.4"/>
      </geometry>
      </collision>

    <inertial>
      <origin rpy="0 0 0" xyz="0 0 0" />
      <mass value="${mass}"/>
      <inertia
	  ixx="${mass / 12.0 * (width*width + height1*height1)}" ixy="0.0" ixz="0.0"
	  iyy="${mass / 12.0 * (height1*height1 + width*width)}" iyz="0.0"
	  izz="${mass / 12.0 * (width*width + width*width)}"/>
    </inertial>

   </link>
   <joint name="right/arm_1_joint" type="continuous">
      <parent link="right/arm_0_bottom" />
      <child link="right/arm_1" />
      <origin xyz="0 0 -0.06" rpy="0 ${3*pi/2} 0" />
   </joint>



   <link name="right/arm_final">
   
      <visual>
         <geometry>
         <box size="0.02 0.02 0.4"/>
            <!--mesh filename="package://arm_description/meshes/new_meshes/arm_1.stl"  /-->
         </geometry>
         <origin rpy="0 0 ${pi}" xyz="0 0 0" />
      </visual>
            <collision>
             <origin rpy="0 0 ${pi}" xyz="0 0 0" />
            <geometry>
        <box size="0.02 0.02 0.4"/>
      </geometry>
      </collision>

    <inertial>
      <origin rpy="0 0 0" xyz="0 0 0" />
      <mass value="${mass}"/>
      <inertia
	  ixx="${mass / 12.0 * (width*width + height1*height1)}" ixy="0.0" ixz="0.0"
	  iyy="${mass / 12.0 * (height1*height1 + width*width)}" iyz="0.0"
	  izz="${mass / 12.0 * (width*width + width*width)}"/>
    </inertial>

   </link>
   <joint name="right/arm_final_joint" type="fixed">
      <parent link="right/arm_1" />
      <child link="right/arm_final" />
      <origin xyz="-0.06 0 -0.06" rpy="0 0 0" />
   </joint>


<!--sssssssssssssssssssssssssssssssssssssssssssssssssssssssssssssssssssssssssssssssss-->
        




  <!-- Instantiate rotors -->
  <xacro:vertical_rotor
    robot_namespace="${namespace}"
    suffix="right"
    direction="cw"
    motor_constant="${motor_constant}"
    moment_constant="${moment_constant}"
    parent="base_link"
    mass_rotor="${mass_rotor}"
    radius_rotor="${radius_rotor}"
    time_constant_up="${time_constant_up}"
    time_constant_down="${time_constant_down}"
    max_rot_velocity="${max_rot_velocity}"
    motor_number="0"
    rotor_drag_coefficient="${rotor_drag_coefficient}"
    rolling_moment_coefficient="${rolling_moment_coefficient}"
    mesh="prop"
    mesh_scale="${mesh_scale_prop}"
    color="DarkGrey">
    <origin xyz="0 -0.390 0" rpy="0 0 0" />
    <xacro:insert_block name="rotor_inertia" />
  </xacro:vertical_rotor>

  <xacro:vertical_rotor
    robot_namespace="${namespace}"
    suffix="left"
    direction="ccw"
    motor_constant="${motor_constant}"
    moment_constant="${moment_constant}"
    parent="base_link"
    mass_rotor="${mass_rotor}"
    radius_rotor="${radius_rotor}"
    time_constant_up="${time_constant_up}"
    time_constant_down="${time_constant_down}"
    max_rot_velocity="${max_rot_velocity}"
    motor_number="1"
    rotor_drag_coefficient="${rotor_drag_coefficient}"
    rolling_moment_coefficient="${rolling_moment_coefficient}"
    mesh="prop"
    mesh_scale="${mesh_scale_prop}"
    color="DarkGrey">
    <origin xyz="0 0.390 0" rpy="0 0 0" />
    <xacro:insert_block name="rotor_inertia" />
  </xacro:vertical_rotor>

  <xacro:vertical_rotor robot_namespace="${namespace}"
    suffix="front_left"
    direction="cw"
    motor_constant="${motor_constant}"
    moment_constant="${moment_constant}"
    parent="base_link"
    mass_rotor="${mass_rotor}"
    radius_rotor="${radius_rotor}"
    time_constant_up="${time_constant_up}"
    time_constant_down="${time_constant_down}"
    max_rot_velocity="${max_rot_velocity}"
    motor_number="2"
    rotor_drag_coefficient="${rotor_drag_coefficient}"
    rolling_moment_coefficient="${rolling_moment_coefficient}"
    mesh="prop"
    mesh_scale="${mesh_scale_prop}"
    color="${color}">
    <origin xyz="0.33775 0.195 0" rpy="0 0 0" />
    <xacro:insert_block name="rotor_inertia" />
  </xacro:vertical_rotor>

  <xacro:vertical_rotor robot_namespace="${namespace}"
    suffix="back_right"
    direction="ccw"
    motor_constant="${motor_constant}"
    moment_constant="${moment_constant}"
    parent="base_link"
    mass_rotor="${mass_rotor}"
    radius_rotor="${radius_rotor}"
    time_constant_up="${time_constant_up}"
    time_constant_down="${time_constant_down}"
    max_rot_velocity="${max_rot_velocity}"
    motor_number="3"
    rotor_drag_coefficient="${rotor_drag_coefficient}"
    rolling_moment_coefficient="${rolling_moment_coefficient}"
    mesh="prop"
    mesh_scale="${mesh_scale_prop}"
    color="DarkGrey">
    <origin xyz="-0.33775 -0.195 0" rpy="0 0 0" />
    <xacro:insert_block name="rotor_inertia" />
  </xacro:vertical_rotor>

  <xacro:vertical_rotor robot_namespace="${namespace}"
    suffix="front_right"
    direction="ccw"
    motor_constant="${motor_constant}"
    moment_constant="${moment_constant}"
    parent="base_link"
    mass_rotor="${mass_rotor}"
    radius_rotor="${radius_rotor}"
    time_constant_up="${time_constant_up}"
    time_constant_down="${time_constant_down}"
    max_rot_velocity="${max_rot_velocity}"
    motor_number="4"
    rotor_drag_coefficient="${rotor_drag_coefficient}"
    rolling_moment_coefficient="${rolling_moment_coefficient}"
    mesh="prop"
    mesh_scale="${mesh_scale_prop}"
    color="${color}">
    <origin xyz="0.33775 -0.195 0" rpy="0 0 0" />
    <xacro:insert_block name="rotor_inertia" />
  </xacro:vertical_rotor>

  <xacro:vertical_rotor robot_namespace="${namespace}"
    suffix="back_left"
    direction="cw"
    motor_constant="${motor_constant}"
    moment_constant="${moment_constant}"
    parent="base_link"
    mass_rotor="${mass_rotor}"
    radius_rotor="${radius_rotor}"
    time_constant_up="${time_constant_up}"
    time_constant_down="${time_constant_down}"
    max_rot_velocity="${max_rot_velocity}"
    motor_number="5"
    rotor_drag_coefficient="${rotor_drag_coefficient}"
    rolling_moment_coefficient="${rolling_moment_coefficient}"
    mesh="prop"
    mesh_scale="${mesh_scale_prop}"
    color="DarkGrey">
    <origin xyz="-0.33775 0.195 0" rpy="0 0 0" />
    <xacro:insert_block name="rotor_inertia" />
  </xacro:vertical_rotor>

</robot>
