<?xml version="1.0" encoding="UTF-8"?>
<robot name="arm4DoF">
   <!-- BASE -->
   <link name="base_link">
      <visual>
         <origin rpy="0 0 0" xyz="0 0 0" />
      </visual>
   </link>

   <!--///////////////////////////////////LEFT ARM//////////////////////////////////-->


   <!-- Joint 0 -->
    <link name="left/arm_0_attachment">
      <visual>
         <geometry>
            <mesh filename="package://arm_description/meshes/new_meshes/arm_0_attachment.stl" />
         </geometry>
          <origin rpy="0 0 0" xyz="0 0 0" />
      </visual>
   </link>

   <joint name="left/arm_0_attachment_joint" type="fixed">
      <parent link="base_link" />
      <child link="left/arm_0_attachment" />
      <origin rpy="0 0 0" xyz="0 0.2 0" />
   </joint>


    <link name="left/arm_0_top">
       <visual>
          <geometry>
             <mesh filename="package://arm_description/meshes/new_meshes/arm_0_top.stl"  />
          </geometry>
          <origin rpy="0 0 ${-pi/2}" xyz="0 0 0" />
       </visual>
    </link>
    <joint name="left/arm_0_top_joint" type="fixed">
       <parent link="left/arm_0_attachment" />
       <child link="left/arm_0_top" />
       <origin rpy="0 0 0" xyz="0 0 -0.03" />
    </joint>

    <link name="left/arm_0_bottom_top_lock">
       <visual>
          <geometry>
             <mesh filename="package://arm_description/meshes/new_meshes/arm_0_bottom_top_lock.stl"  />
          </geometry>
       </visual>
    </link>
    <joint name="left/arm_0_bottom_top_lock_joint" type="fixed">
       <parent link="left/arm_0_top" />
       <child link="left/arm_0_bottom_top_lock" />
       <origin rpy="0 0 0" xyz="0 0 0" />
    </joint>


   <link name="left/arm_0_bottom">
      <visual>
         <geometry>
            <mesh filename="package://arm_description/meshes/new_meshes/arm_0_bottom.stl"  />
         </geometry>
         <origin rpy="0 ${pi/2} 0" xyz="0 0 0" />
      </visual>
   </link>
   <joint name="left/arm_0_bottom_joint" type="continuous">
      <parent link="left/arm_0_bottom_top_lock" />
      <child link="left/arm_0_bottom" />
      <origin rpy="0 ${-pi/2} ${-pi/2}" xyz="0 0 -0.005" />
   </joint>

    <link name="left/arm_0_bottom_case">
      <visual>
         <geometry>
            <mesh filename="package://arm_description/meshes/new_meshes/arm_0_bottom_case.stl"  />
         </geometry>
         <origin rpy="0 ${-pi/2} ${pi}" xyz="-0.015 0.0345 -0.025" />
      </visual>
   </link>
   <joint name="left/arm_0_bottom_case_joint" type="fixed">
      <parent link="left/arm_0_bottom" />
      <child link="left/arm_0_bottom_case" />
      <origin rpy="0 0 0" xyz="-0.017 0 0" />
   </joint>

   
   <link name="left/arm_1">
      <visual>
         <geometry>
            <mesh filename="package://arm_description/meshes/new_meshes/arm_1.stl"  />
         </geometry>
         <origin rpy="0 0 ${pi}" xyz="0 0 0" />
      </visual>
   </link>
   <joint name="left/arm_1_joint" type="continuous">
      <parent link="left/arm_0_bottom_case" />
      <child link="left/arm_1" />
      <origin xyz="0 0 0" rpy="0 ${3*pi/2} 0" />
   </joint>


 <link name="left/arm_1_case">
      <visual>
         <geometry>
            <mesh filename="package://arm_description/meshes/new_meshes/arm_1_case.stl"  />
         </geometry>
         <origin rpy="${pi/2} 0 0" xyz="-0.02 -0.01 -0.035" />
      </visual>
   </link>
   <joint name="left/arm_1_case_joint" type="fixed">
      <parent link="left/arm_1" />
      <child link="left/arm_1_case" />
      <origin xyz="0 0 0.145" rpy="0 0 0" />
   </joint>
   
   
   <link name="left/arm_2_microservo">
      <visual>
         <geometry>
            <mesh filename="package://arm_description/meshes/new_meshes/arm_2_microservo.stl" />
         </geometry>
         <origin rpy="0 0 ${pi}" xyz="0 0 0" />
      </visual>
   </link>
   <joint name="left/arm_2_microservo_joint" type="continuous">
      <parent link="left/arm_1_case" />
      <child link="left/arm_2_microservo" />
      <origin xyz="0 0 0.0085" rpy="0 0 0"/>
   </joint>

<link name="left/arm_2_microservo_case">
      <visual>
         <geometry>
            <mesh filename="package://arm_description/meshes/new_meshes/arm_2_microservo_case.stl" />
         </geometry>
         <origin rpy="0 0 0" xyz="0.027 -0.006 0" />
      </visual>
   </link>
   <joint name="left/arm_2_microservo_case_joint" type="fixed">
      <parent link="left/arm_2_microservo" />
      <child link="left/arm_2_microservo_case" />
      <origin xyz="0 0 0.057" rpy="0 0 0"/>
   </joint>

<link name="left/arm_2_case_bearing">
      <visual>
         <geometry>
            <mesh filename="package://arm_description/meshes/new_meshes/arm_2_case_bearing.stl" />
         </geometry>
         <origin rpy="${pi/2} ${pi} ${pi/2}" xyz="0.027 -0.013 0.01" />
      </visual>
   </link>
   <joint name="left/arm_2_case_bearing_joint" type="fixed">
      <parent link="left/arm_2_microservo_case" />
      <child link="left/arm_2_case_bearing" />
      <origin xyz="0 0 0.072" rpy="0 0 0"/>
   </joint>

<link name="left/end_effector_connector">
      <visual>
         <geometry>
            <mesh filename="package://arm_description/meshes/new_meshes/end_effector_connector.stl" />
         </geometry>
         <origin rpy="0 0 0" xyz="0 0 -0.069" />
      </visual>
   </link>
   <joint name="left/end_effector_connector_joint" type="fixed">
      <parent link="left/arm_2_case_bearing" />
      <child link="left/end_effector_connector" />
      <origin xyz="0 0 0" rpy="0 0 0"/>
   </joint>

<link name="left/Positioner_Rotor_HAND">
      <visual>
         <geometry>
            <mesh filename="package://arm_description/meshes/new_meshes/positioner/Positioner_Rotor_HAND.stl" />
         </geometry>
         <origin rpy="0 0 0" xyz="0 0 -0.054" />
      </visual>
   </link>
   <joint name="left/Positioner_Rotor_HAND_joint" type="fixed">
      <parent link="left/end_effector_connector" />
      <child link="left/Positioner_Rotor_HAND" />
      <origin xyz="0 0 0" rpy="0 0 ${pi}"/>
   </joint>

<link name="left/Positioner_HAND">
      <visual>
         <geometry>
            <mesh filename="package://arm_description/meshes/new_meshes/positioner/Positioner_HAND.stl" />
         </geometry>
         <origin rpy="0 0 0" xyz="0 0 0" />
      </visual>
   </link>
   <joint name="left/Positioner_HAND_joint" type="continuous">
      <parent link="left/Positioner_Rotor_HAND" />
      <child link="left/Positioner_HAND" />
      <origin xyz="0 0 0.027" rpy="0 0 0"/>
   </joint>

<link name="left/Positioner_1">
      <visual>
         <geometry>
            <mesh filename="package://arm_description/meshes/new_meshes/positioner/Positioner_1.stl" />
         </geometry>
         <origin rpy="0 ${-pi/2} 0" xyz="0.022 0 0" />
      </visual>
   </link>
   <joint name="left/Positioner_1_joint" type="continuous">
      <parent link="left/Positioner_HAND" />
      <child link="left/Positioner_1" />
      <origin xyz="0 0 0.070" rpy="0 0 ${pi/2}"/>
   </joint>

<link name="left/Positioner_2">
      <visual>
         <geometry>
            <mesh filename="package://arm_description/meshes/new_meshes/positioner/Positioner_2.stl" />
         </geometry>
         <origin rpy="0 ${-pi/2} 0" xyz="0.023 0 0" />
      </visual>
   </link>
   <joint name="left/Positioner_2_joint" type="continuous">
      <parent link="left/Positioner_1" />
      <child link="left/Positioner_2" />
      <origin xyz="0 0 0.153" rpy="0 0 0"/>
   </joint>

<link name="left/Positioner_BASE">
      <visual>
         <geometry>
            <mesh filename="package://arm_description/meshes/new_meshes/positioner/Positioner_BASE.stl" />
         </geometry>
         <origin rpy="0 ${pi} ${-pi/2}" xyz="0.005 0 0.068" />
      </visual>
   </link>
   <joint name="left/Positioner_BASE_joint" type="continuous">
      <parent link="left/Positioner_2" />
      <child link="left/Positioner_BASE" />
      <origin xyz="0 0 0.105" rpy="0 0 0"/>
   </joint>

<link name="left/Positioner_Fija_BASE">
      <visual>
         <geometry>
            <mesh filename="package://arm_description/meshes/new_meshes/positioner/Positioner_Fija_BASE.stl" />
         </geometry>
         <origin rpy="${pi/2} 0 ${pi/2}" xyz="0 0 0" />
      </visual>
   </link>
   <joint name="left/Positioner_Fija_BASE_joint" type="continuous">
      <parent link="left/Positioner_BASE" />
      <child link="left/Positioner_Fija_BASE" />
      <origin xyz="0.005 0 0.075" rpy="0 ${pi/2} 0"/>
   </joint>


<link name="left/Positioner_Adapter_Der_1">
      <visual>
         <geometry>
            <mesh filename="package://arm_description/meshes/new_meshes/positioner/Positioner_Adapter_Der.stl" />
         </geometry>
         <origin rpy="${pi/2} 0 ${pi/2}" xyz="-0.0043 0.034 0.036" />
      </visual>
   </link>
   <joint name="left/Positioner_Adapter_Der_1_joint" type="fixed">
      <parent link="left/Positioner_Fija_BASE" />
      <child link="left/Positioner_Adapter_Der_1" />
      <origin xyz="0 0 0" rpy="0 0 0"/>
   </joint>

<link name="left/Positioner_Adapter_Der_2">
      <visual>
         <geometry>
            <mesh filename="package://arm_description/meshes/new_meshes/positioner/Positioner_Adapter_Der.stl" />
         </geometry>
         <origin rpy="${-pi/2} 0 ${-pi/2}" xyz="-0.0043 -0.034 -0.036" />
      </visual>
   </link>
   <joint name="left/Positioner_Adapter_Der_2_joint" type="fixed">
      <parent link="left/Positioner_Fija_BASE" />
      <child link="left/Positioner_Adapter_Der_2" />
      <origin xyz="0 0 0" rpy="0 0 0"/>
   </joint>


<link name="left/Positioner_Adapter_Izq_1">
      <visual>
         <geometry>
            <mesh filename="package://arm_description/meshes/new_meshes/positioner/Positioner_Adapter_Izq.stl" />
         </geometry>
         <origin rpy="${pi/2} 0 ${pi/2}" xyz="-0.0043 0.034 -0.036" />
      </visual>
   </link>
   <joint name="left/Positioner_Adapter_Izq_1_joint" type="fixed">
      <parent link="left/Positioner_Fija_BASE" />
      <child link="left/Positioner_Adapter_Izq_1" />
      <origin xyz="0 0 0" rpy="0 0 0"/>
   </joint>

<link name="left/Positioner_Adapter_Izq_2">
      <visual>
         <geometry>
            <mesh filename="package://arm_description/meshes/new_meshes/positioner/Positioner_Adapter_Izq.stl" />
         </geometry>
         <origin rpy="${-pi/2} 0 ${-pi/2}" xyz="-0.0043 -0.034 0.036" />
      </visual>
   </link>
   <joint name="left/Positioner_Adapter_Izq_2_joint" type="fixed">
      <parent link="left/Positioner_Fija_BASE" />
      <child link="left/Positioner_Adapter_Izq_2" />
      <origin xyz="0 0 0" rpy="0 0 0"/>
   </joint>

<!--///////////////////////////////////Right ARM//////////////////////////////////-->
    
<!-- Joint 0 -->
    <link name="right/arm_0_attachment">
      <visual>
         <geometry>
            <mesh filename="package://arm_description/meshes/new_meshes/arm_0_attachment.stl" />
         </geometry>
          <origin rpy="0 0 0" xyz="0 0 0" />
      </visual>
   </link>
   <joint name="right/arm_0_attachment_joint" type="fixed">
      <parent link="base_link" />
      <child link="right/arm_0_attachment" />
      <origin rpy="0 0 0" xyz="0 -0.2 0" />
   </joint>


    <link name="right/arm_0_top">
       <visual>
          <geometry>
             <mesh filename="package://arm_description/meshes/new_meshes/arm_0_top.stl"  />
          </geometry>
          <origin rpy="0 0 ${-pi/2}" xyz="0 0 0" />
       </visual>
    </link>
    <joint name="right/arm_0_top_joint" type="fixed">
       <parent link="right/arm_0_attachment" />
       <child link="right/arm_0_top" />
       <origin rpy="0 0 0" xyz="0 0 -0.03" />
    </joint>

    <link name="right/arm_0_bottom_top_lock">
       <visual>
          <geometry>
             <mesh filename="package://arm_description/meshes/new_meshes/arm_0_bottom_top_lock.stl"  />
          </geometry>
       </visual>
    </link>
    <joint name="right/arm_0_bottom_top_lock_joint" type="fixed">
       <parent link="right/arm_0_top" />
       <child link="right/arm_0_bottom_top_lock" />
       <origin rpy="0 0 0" xyz="0 0 0" />
    </joint>


   <link name="right/arm_0_bottom">
      <visual>
         <geometry>
            <mesh filename="package://arm_description/meshes/new_meshes/arm_0_bottom.stl"  />
         </geometry>
         <origin rpy="0 ${pi/2} 0" xyz="0 0 0" />
      </visual>
   </link>
   <joint name="right/arm_0_bottom_joint" type="continuous">
      <parent link="right/arm_0_bottom_top_lock" />
      <child link="right/arm_0_bottom" />
      <origin rpy="0 ${-pi/2} ${-pi/2}" xyz="0 0 -0.005" />
   </joint>

    <link name="right/arm_0_bottom_case">
      <visual>
         <geometry>
            <mesh filename="package://arm_description/meshes/new_meshes/arm_0_bottom_case.stl"  />
         </geometry>
         <origin rpy="0 ${-pi/2} ${pi}" xyz="-0.015 0.0345 -0.025" />
      </visual>
   </link>
   <joint name="right/arm_0_bottom_case_joint" type="fixed">
      <parent link="right/arm_0_bottom" />
      <child link="right/arm_0_bottom_case" />
      <origin rpy="0 0 0" xyz="-0.017 0 0" />
   </joint>

   
   <link name="right/arm_1">
      <visual>
         <geometry>
            <mesh filename="package://arm_description/meshes/new_meshes/arm_1.stl"  />
         </geometry>
         <origin rpy="0 0 ${pi}" xyz="0 0 0" />
      </visual>
   </link>
   <joint name="right/arm_1_joint" type="continuous">
      <parent link="right/arm_0_bottom_case" />
      <child link="right/arm_1" />
      <origin xyz="0 0 0" rpy="0 ${3*pi/2} 0" />
   </joint>


 <link name="right/arm_1_case">
      <visual>
         <geometry>
            <mesh filename="package://arm_description/meshes/new_meshes/arm_1_case.stl"  />
         </geometry>
         <origin rpy="${pi/2} 0 0" xyz="-0.02 -0.01 -0.035" />
      </visual>
   </link>
   <joint name="right/arm_1_case_joint" type="fixed">
      <parent link="right/arm_1" />
      <child link="right/arm_1_case" />
      <origin xyz="0 0 0.145" rpy="0 0 0" />
   </joint>
   
  
   <link name="right/arm_2_microservo">
      <visual>
         <geometry>
            <mesh filename="package://arm_description/meshes/new_meshes/arm_2_microservo.stl" />
         </geometry>
         <origin rpy="0 0 ${pi}" xyz="0 0 0" />
      </visual>
   </link>
   <joint name="right/arm_2_microservo_joint" type="continuous">
      <parent link="right/arm_1_case" />
      <child link="right/arm_2_microservo" />
      <origin xyz="0 0 0.0085" rpy="0 0 0"/>
   </joint>

<link name="right/arm_2_microservo_case">
      <visual>
         <geometry>
            <mesh filename="package://arm_description/meshes/new_meshes/arm_2_microservo_case.stl" />
         </geometry>
         <origin rpy="0 0 0" xyz="0.027 -0.006 0" />
      </visual>
   </link>
   <joint name="right/arm_2_microservo_case_joint" type="fixed">
      <parent link="right/arm_2_microservo" />
      <child link="right/arm_2_microservo_case" />
      <origin xyz="0 0 0.057" rpy="0 0 0"/>
   </joint>

<link name="right/arm_2_case_bearing">
      <visual>
         <geometry>
            <mesh filename="package://arm_description/meshes/new_meshes/arm_2_case_bearing.stl" />
         </geometry>
         <origin rpy="${pi/2} ${pi} ${pi/2}" xyz="0.027 -0.013 0.01" />
      </visual>
   </link>
   <joint name="right/arm_2_case_bearing_joint" type="fixed">
      <parent link="right/arm_2_microservo_case" />
      <child link="right/arm_2_case_bearing" />
      <origin xyz="0 0 0.072" rpy="0 0 0"/>
   </joint>

<link name="right/end_effector_connector">
      <visual>
         <geometry>
            <mesh filename="package://arm_description/meshes/new_meshes/end_effector_connector.stl" />
         </geometry>
         <origin rpy="0 0 0" xyz="0 0 -0.069" />
      </visual>
   </link>
   <joint name="right/end_effector_connector_joint" type="fixed">
      <parent link="right/arm_2_case_bearing" />
      <child link="right/end_effector_connector" />
      <origin xyz="0 0 0" rpy="0 0 0"/>
   </joint>

<link name="right/Positioner_Rotor_HAND">
      <visual>
         <geometry>
            <mesh filename="package://arm_description/meshes/new_meshes/positioner/Positioner_Rotor_HAND.stl" />
         </geometry>
         <origin rpy="0 0 0" xyz="0 0 -0.054" />
      </visual>
   </link>
   <joint name="right/Positioner_Rotor_HAND_joint" type="fixed">
      <parent link="right/end_effector_connector" />
      <child link="right/Positioner_Rotor_HAND" />
      <origin xyz="0 0 0" rpy="0 0 ${pi}"/>
   </joint>

<link name="right/Positioner_HAND">
      <visual>
         <geometry>
            <mesh filename="package://arm_description/meshes/new_meshes/positioner/Positioner_HAND.stl" />
         </geometry>
         <origin rpy="0 0 0" xyz="0 0 0" />
      </visual>
   </link>
   <joint name="right/Positioner_HAND_joint" type="continuous">
      <parent link="right/Positioner_Rotor_HAND" />
      <child link="right/Positioner_HAND" />
      <origin xyz="0 0 0.027" rpy="0 0 0"/>
   </joint>

<link name="right/Positioner_1">
      <visual>
         <geometry>
            <mesh filename="package://arm_description/meshes/new_meshes/positioner/Positioner_1.stl" />
         </geometry>
         <origin rpy="0 ${-pi/2} 0" xyz="0.022 0 0" />
      </visual>
   </link>
   <joint name="right/Positioner_1_joint" type="continuous">
      <parent link="right/Positioner_HAND" />
      <child link="right/Positioner_1" />
      <origin xyz="0 0 0.070" rpy="0 0 ${pi/2}"/>
   </joint>

<link name="right/Positioner_2">
      <visual>
         <geometry>
            <mesh filename="package://arm_description/meshes/new_meshes/positioner/Positioner_2.stl" />
         </geometry>
         <origin rpy="0 ${-pi/2} 0" xyz="0.023 0 0" />
      </visual>
   </link>
   <joint name="right/Positioner_2_joint" type="continuous">
      <parent link="right/Positioner_1" />
      <child link="right/Positioner_2" />
      <origin xyz="0 0 0.153" rpy="0 0 0"/>
   </joint>

<link name="right/Positioner_BASE">
      <visual>
         <geometry>
            <mesh filename="package://arm_description/meshes/new_meshes/positioner/Positioner_BASE.stl" />
         </geometry>
         <origin rpy="0 ${pi} ${-pi/2}" xyz="0.005 0 0.068" />
      </visual>
   </link>
   <joint name="right/Positioner_BASE_joint" type="continuous">
      <parent link="right/Positioner_2" />
      <child link="right/Positioner_BASE" />
      <origin xyz="0 0 0.105" rpy="0 0 0"/>
   </joint>

<link name="right/Positioner_Fija_BASE">
      <visual>
         <geometry>
            <mesh filename="package://arm_description/meshes/new_meshes/positioner/Positioner_Fija_BASE.stl" />
         </geometry>
         <origin rpy="${pi/2} 0 ${pi/2}" xyz="0 0 0" />
      </visual>
   </link>
   <joint name="right/Positioner_Fija_BASE_joint" type="continuous">
      <parent link="right/Positioner_BASE" />
      <child link="right/Positioner_Fija_BASE" />
      <origin xyz="0.005 0 0.075" rpy="0 ${pi/2} 0"/>
   </joint>

<link name="right/Positioner_Adapter_Der_1">
      <visual>
         <geometry>
            <mesh filename="package://arm_description/meshes/new_meshes/positioner/Positioner_Adapter_Der.stl" />
         </geometry>
         <origin rpy="${pi/2} 0 ${pi/2}" xyz="-0.0043 0.034 0.036" />
      </visual>
   </link>
   <joint name="right/Positioner_Adapter_Der_1_joint" type="fixed">
      <parent link="right/Positioner_Fija_BASE" />
      <child link="right/Positioner_Adapter_Der_1" />
      <origin xyz="0 0 0" rpy="0 0 0"/>
   </joint>

<link name="right/Positioner_Adapter_Der_2">
      <visual>
         <geometry>
            <mesh filename="package://arm_description/meshes/new_meshes/positioner/Positioner_Adapter_Der.stl" />
         </geometry>
         <origin rpy="${-pi/2} 0 ${-pi/2}" xyz="-0.0043 -0.034 -0.036" />
      </visual>
   </link>
   <joint name="right/Positioner_Adapter_Der_2_joint" type="fixed">
      <parent link="right/Positioner_Fija_BASE" />
      <child link="right/Positioner_Adapter_Der_2" />
      <origin xyz="0 0 0" rpy="0 0 0"/>
   </joint>

<link name="right/Positioner_Adapter_Izq_1">
      <visual>
         <geometry>
            <mesh filename="package://arm_description/meshes/new_meshes/positioner/Positioner_Adapter_Izq.stl" />
         </geometry>
         <origin rpy="${pi/2} 0 ${pi/2}" xyz="-0.0043 0.034 -0.036" />
      </visual>
   </link>
   <joint name="right/Positioner_Adapter_Izq_1_joint" type="fixed">
      <parent link="right/Positioner_Fija_BASE" />
      <child link="right/Positioner_Adapter_Izq_1" />
      <origin xyz="0 0 0" rpy="0 0 0"/>
   </joint>

<link name="right/Positioner_Adapter_Izq_2">
      <visual>
         <geometry>
            <mesh filename="package://arm_description/meshes/new_meshes/positioner/Positioner_Adapter_Izq.stl" />
         </geometry>
         <origin rpy="${-pi/2} 0 ${-pi/2}" xyz="-0.0043 -0.034 0.036" />
      </visual>
   </link>
   <joint name="right/Positioner_Adapter_Izq_2_joint" type="fixed">
      <parent link="right/Positioner_Fija_BASE" />
      <child link="right/Positioner_Adapter_Izq_2" />
      <origin xyz="0 0 0" rpy="0 0 0"/>
   </joint>

  <gazebo>
    <plugin name="gazebo_ros_control" filename="libgazebo_ros_control.so">
      <robotNamespace>/aeroarms</robotNamespace>
    </plugin>
  </gazebo>




</robot>
